<sdf version='1.7'>
  <model name='spm_wrist'>
    <joint name='world_joint' type='fixed'>
      <pose relative_to='__model__'>0 0 0.2 1.5708 -0 0</pose>
      <parent>world</parent>
      <child>base_link</child>
    </joint>
    <link name='base_link'>
      <pose relative_to='world_joint'>0 0 0 0 -0 0</pose>
      <inertial>
        <pose>0 0.026986 -1e-06 0 -0 0</pose>
        <mass>0.219161</mass>
        <inertia>
          <ixx>0.000229267</ixx>
          <ixy>1.2267e-09</ixy>
          <ixz>3.27532e-13</ixz>
          <iyy>0.000204178</iyy>
          <iyz>-5.60645e-09</iyz>
          <izz>0.000230267</izz>
        </inertia>
      </inertial>
      <collision name='base_link_collision'>
        <pose>0 0 0 0 -0 0</pose>
        <geometry>
          <mesh>
            <scale>0.001 0.001 0.001</scale>
            <uri>model://spm_wrist_description/meshes/base_link.stl</uri>
          </mesh>
        </geometry>
      </collision>
      <collision name='base_link_fixed_joint_lump__ServoMotor1_collision_1'>
        <pose>0 0 0 0 -0 0</pose>
        <geometry>
          <mesh>
            <scale>0.001 0.001 0.001</scale>
            <uri>model://spm_wrist_description/meshes/servo_motor_v2_1.stl</uri>
          </mesh>
        </geometry>
      </collision>
      <collision name='base_link_fixed_joint_lump__Bottom1_collision_2'>
        <pose>0 0 0 0 -0 0</pose>
        <geometry>
          <mesh>
            <scale>0.001 0.001 0.001</scale>
            <uri>model://spm_wrist_description/meshes/Bottom_v2_1.stl</uri>
          </mesh>
        </geometry>
      </collision>
      <collision name='base_link_fixed_joint_lump__Bottom2_collision_3'>
        <pose>0 0 0 0 -0 0</pose>
        <geometry>
          <mesh>
            <scale>0.001 0.001 0.001</scale>
            <uri>model://spm_wrist_description/meshes/Bottom_v2_2.stl</uri>
          </mesh>
        </geometry>
      </collision>
      <collision name='base_link_fixed_joint_lump__Bottom3_collision_4'>
        <pose>0 0 0 0 -0 0</pose>
        <geometry>
          <mesh>
            <scale>0.001 0.001 0.001</scale>
            <uri>model://spm_wrist_description/meshes/Bottom_v2_3.stl</uri>
          </mesh>
        </geometry>
      </collision>
      <collision name='base_link_fixed_joint_lump__Top_collision_5'>
        <pose>0 0 0 0 -0 0</pose>
        <geometry>
          <mesh>
            <scale>0.001 0.001 0.001</scale>
            <uri>model://spm_wrist_description/meshes/Top_v2_1.stl</uri>
          </mesh>
        </geometry>
      </collision>
      <collision name='base_link_fixed_joint_lump__ServoMotor2_collision_6'>
        <pose>0 0 0 0 -0 0</pose>
        <geometry>
          <mesh>
            <scale>0.001 0.001 0.001</scale>
            <uri>model://spm_wrist_description/meshes/servo_motor_v2_2.stl</uri>
          </mesh>
        </geometry>
      </collision>
      <collision name='base_link_fixed_joint_lump__ServoMotor3_collision_7'>
        <pose>0 0 0 0 -0 0</pose>
        <geometry>
          <mesh>
            <scale>0.001 0.001 0.001</scale>
            <uri>model://spm_wrist_description/meshes/servo_motor_v2_3.stl</uri>
          </mesh>
        </geometry>
      </collision>
      <visual name='base_link_visual'>
        <pose>0 0 0 0 -0 0</pose>
        <geometry>
          <mesh>
            <scale>0.001 0.001 0.001</scale>
            <uri>model://spm_wrist_description/meshes/base_link.stl</uri>
          </mesh>
        </geometry>
      </visual>
      <visual name='base_link_fixed_joint_lump__ServoMotor1_visual_1'>
        <pose>0 0 0 0 -0 0</pose>
        <geometry>
          <mesh>
            <scale>0.001 0.001 0.001</scale>
            <uri>model://spm_wrist_description/meshes/servo_motor_v2_1.stl</uri>
          </mesh>
        </geometry>
      </visual>
      <visual name='base_link_fixed_joint_lump__Bottom1_visual_2'>
        <pose>0 0 0 0 -0 0</pose>
        <geometry>
          <mesh>
            <scale>0.001 0.001 0.001</scale>
            <uri>model://spm_wrist_description/meshes/Bottom_v2_1.stl</uri>
          </mesh>
        </geometry>
      </visual>
      <visual name='base_link_fixed_joint_lump__Bottom2_visual_3'>
        <pose>0 0 0 0 -0 0</pose>
        <geometry>
          <mesh>
            <scale>0.001 0.001 0.001</scale>
            <uri>model://spm_wrist_description/meshes/Bottom_v2_2.stl</uri>
          </mesh>
        </geometry>
      </visual>
      <visual name='base_link_fixed_joint_lump__Bottom3_visual_4'>
        <pose>0 0 0 0 -0 0</pose>
        <geometry>
          <mesh>
            <scale>0.001 0.001 0.001</scale>
            <uri>model://spm_wrist_description/meshes/Bottom_v2_3.stl</uri>
          </mesh>
        </geometry>
      </visual>
      <visual name='base_link_fixed_joint_lump__Top_visual_5'>
        <pose>0 0 0 0 -0 0</pose>
        <geometry>
          <mesh>
            <scale>0.001 0.001 0.001</scale>
            <uri>model://spm_wrist_description/meshes/Top_v2_1.stl</uri>
          </mesh>
        </geometry>
      </visual>
      <visual name='base_link_fixed_joint_lump__ServoMotor2_visual_6'>
        <pose>0 0 0 0 -0 0</pose>
        <geometry>
          <mesh>
            <scale>0.001 0.001 0.001</scale>
            <uri>model://spm_wrist_description/meshes/servo_motor_v2_2.stl</uri>
          </mesh>
        </geometry>
      </visual>
      <visual name='base_link_fixed_joint_lump__ServoMotor3_visual_7'>
        <pose>0 0 0 0 -0 0</pose>
        <geometry>
          <mesh>
            <scale>0.001 0.001 0.001</scale>
            <uri>model://spm_wrist_description/meshes/servo_motor_v2_3.stl</uri>
          </mesh>
        </geometry>
      </visual>
    </link>
    <joint name='LngSpur_Joint' type='revolute'>
      <pose relative_to='base_link'>-0.015556 0.0352 0.008981 0 -0 0</pose>
      <parent>base_link</parent>
      <child>AxisConnector1</child>
      <axis>
        <xyz>0 -1 0</xyz>
        <limit>
          <lower>-1e+16</lower>
          <upper>1e+16</upper>
        </limit>
        <dynamics>
          <spring_reference>0</spring_reference>
          <spring_stiffness>0</spring_stiffness>
        </dynamics>
      </axis>
    </joint>
    <link name='AxisConnector1'>
      <pose relative_to='LngSpur_Joint'>0 0 0 0 -0 0</pose>
      <inertial>
        <pose>0 0.011097 0 0 -0 0</pose>
        <mass>0.00633253</mass>
        <inertia>
          <ixx>9.41591e-07</ixx>
          <ixy>3.45384e-18</ixy>
          <ixz>3.09659e-29</ixz>
          <iyy>1.5336e-07</iyy>
          <iyz>-7.68482e-18</iyz>
          <izz>9.41591e-07</izz>
        </inertia>
      </inertial>
      <collision name='AxisConnector1_collision'>
        <pose>0.015556 -0.0352 -0.008981 0 -0 0</pose>
        <geometry>
          <mesh>
            <scale>0.001 0.001 0.001</scale>
            <uri>model://spm_wrist_description/meshes/AxisConnector_v3_1.stl</uri>
          </mesh>
        </geometry>
      </collision>
      <collision name='AxisConnector1_fixed_joint_lump__LngSpur_collision_1'>
        <pose>0.015556 -0.0352 -0.008981 0 -0 0</pose>
        <geometry>
          <mesh>
            <scale>0.001 0.001 0.001</scale>
            <uri>model://spm_wrist_description/meshes/LngSpur_v2_1.stl</uri>
          </mesh>
        </geometry>
      </collision>
      <visual name='AxisConnector1_visual'>
        <pose>0.015556 -0.0352 -0.008981 0 -0 0</pose>
        <geometry>
          <mesh>
            <scale>0.001 0.001 0.001</scale>
            <uri>model://spm_wrist_description/meshes/AxisConnector_v3_1.stl</uri>
          </mesh>
        </geometry>
      </visual>
      <visual name='AxisConnector1_fixed_joint_lump__LngSpur_visual_1'>
        <pose>0.015556 -0.0352 -0.008981 0 -0 0</pose>
        <geometry>
          <mesh>
            <scale>0.001 0.001 0.001</scale>
            <uri>model://spm_wrist_description/meshes/LngSpur_v2_1.stl</uri>
          </mesh>
        </geometry>
      </visual>
    </link>
    <joint name='Revolute13' type='revolute'>
      <pose relative_to='base_link'>0 0.0405 0 0 -0 0</pose>
      <parent>base_link</parent>
      <child>Ring1</child>
      <axis>
        <xyz>0 1 0</xyz>
        <limit>
          <lower>-1e+16</lower>
          <upper>1e+16</upper>
        </limit>
        <dynamics>
          <spring_reference>0</spring_reference>
          <spring_stiffness>0</spring_stiffness>
        </dynamics>
      </axis>
    </joint>
    <link name='Ring1'>
      <pose relative_to='Revolute13'>0 0 0 0 -0 0</pose>
      <inertial>
        <pose>0.014553 0.017205 9e-06 0 -0 0</pose>
        <mass>0.0160866</mass>
        <inertia>
          <ixx>8.19026e-06</ixx>
          <ixy>-3.10905e-06</ixy>
          <ixz>-1.42878e-09</ixz>
          <iyy>1.20299e-05</iyy>
          <iyz>-1.4661e-09</iyz>
          <izz>1.22202e-05</izz>
        </inertia>
      </inertial>
      <collision name='Ring1_collision'>
        <pose>0 -0.0405 0 0 -0 0</pose>
        <geometry>
          <mesh>
            <scale>0.001 0.001 0.001</scale>
            <uri>model://spm_wrist_description/meshes/Ring_v2_1.stl</uri>
          </mesh>
        </geometry>
      </collision>
      <collision name='Ring1_fixed_joint_lump__LongArm_collision_1'>
        <pose>0 -0.0405 0 0 -0 0</pose>
        <geometry>
          <mesh>
            <scale>0.001 0.001 0.001</scale>
            <uri>model://spm_wrist_description/meshes/LongArm_v2_1.stl</uri>
          </mesh>
        </geometry>
      </collision>
      <visual name='Ring1_visual'>
        <pose>0 -0.0405 0 0 -0 0</pose>
        <geometry>
          <mesh>
            <scale>0.001 0.001 0.001</scale>
            <uri>model://spm_wrist_description/meshes/Ring_v2_1.stl</uri>
          </mesh>
        </geometry>
      </visual>
      <visual name='Ring1_fixed_joint_lump__LongArm_visual_1'>
        <pose>0 -0.0405 0 0 -0 0</pose>
        <geometry>
          <mesh>
            <scale>0.001 0.001 0.001</scale>
            <uri>model://spm_wrist_description/meshes/LongArm_v2_1.stl</uri>
          </mesh>
        </geometry>
      </visual>
    </link>
    <joint name='PlatformSupportLink1_Joint' type='revolute'>
      <pose relative_to='Ring1'>0.031815 0.061098 0 0 -0 0</pose>
      <parent>Ring1</parent>
      <child>PlatformSupportLink1</child>
      <axis>
        <xyz>-0.707107 0.707107 0</xyz>
        <limit>
          <lower>-1e+16</lower>
          <upper>1e+16</upper>
        </limit>
        <dynamics>
          <spring_reference>0</spring_reference>
          <spring_stiffness>0</spring_stiffness>
        </dynamics>
      </axis>
    </joint>
    <link name='PlatformSupportLink1'>
      <pose relative_to='PlatformSupportLink1_Joint'>0 0 0 0 -0 0</pose>
      <inertial>
        <pose>-0.008186 0.023544 0.017143 0 -0 0</pose>
        <mass>0.0101513</mass>
        <inertia>
          <ixx>3e-06</ixx>
          <ixy>1e-06</ixy>
          <ixz>1e-06</ixz>
          <iyy>3e-06</iyy>
          <iyz>-1e-06</iyz>
          <izz>4e-06</izz>
        </inertia>
      </inertial>
      <collision name='PlatformSupportLink1_collision'>
        <pose>-0.031815 -0.101598 0 0 -0 0</pose>
        <geometry>
          <mesh>
            <scale>0.001 0.001 0.001</scale>
            <uri>model://spm_wrist_description/meshes/PlatformSupportLink_v2_1.stl</uri>
          </mesh>
        </geometry>
      </collision>
      <visual name='PlatformSupportLink1_visual'>
        <pose>-0.031815 -0.101598 0 0 -0 0</pose>
        <geometry>
          <mesh>
            <scale>0.001 0.001 0.001</scale>
            <uri>model://spm_wrist_description/meshes/PlatformSupportLink_v2_1.stl</uri>
          </mesh>
        </geometry>
      </visual>
    </link>
    <joint name='Platform_Joint1' type='revolute'>
      <pose relative_to='PlatformSupportLink1'>-0.03093 0.032415 0.02748 0 -0 0</pose>
      <parent>PlatformSupportLink1</parent>
      <child>Platform</child>
      <axis>
        <xyz>-0.027239 -0.027239 -0.999258</xyz>
        <limit>
          <lower>-1e+16</lower>
          <upper>1e+16</upper>
        </limit>
        <dynamics>
          <spring_reference>0</spring_reference>
          <spring_stiffness>0</spring_stiffness>
        </dynamics>
      </axis>
    </joint>
    <link name='Platform'>
      <pose relative_to='Platform_Joint1'>0 0 0 0 -0 0</pose>
      <inertial>
        <pose>-0.00075 0.001476 -0.02754 0 -0 0</pose>
        <mass>0.00869409</mass>
        <inertia>
          <ixx>2e-06</ixx>
          <ixy>0</ixy>
          <ixz>0</ixz>
          <iyy>3e-06</iyy>
          <iyz>0</iyz>
          <izz>2e-06</izz>
        </inertia>
      </inertial>
      <collision name='Platform_collision'>
        <pose>-0.000885 -0.134013 -0.02748 0 -0 0</pose>
        <geometry>
          <mesh>
            <scale>0.001 0.001 0.001</scale>
            <uri>model://spm_wrist_description/meshes/Platform_v2_1.stl</uri>
          </mesh>
        </geometry>
      </collision>
      <visual name='Platform_visual'>
        <pose>-0.000885 -0.134013 -0.02748 0 -0 0</pose>
        <geometry>
          <mesh>
            <scale>0.001 0.001 0.001</scale>
            <uri>model://spm_wrist_description/meshes/Platform_v2_1.stl</uri>
          </mesh>
        </geometry>
      </visual>
    </link>
    <joint name='Revolute14' type='revolute'>
      <pose relative_to='base_link'>0 0.0565 0 0 -0 0</pose>
      <parent>base_link</parent>
      <child>Ring2</child>
      <axis>
        <xyz>0 1 0</xyz>
        <limit>
          <lower>-1e+16</lower>
          <upper>1e+16</upper>
        </limit>
        <dynamics>
          <spring_reference>0</spring_reference>
          <spring_stiffness>0</spring_stiffness>
        </dynamics>
      </axis>
    </joint>
    <link name='Ring2'>
      <pose relative_to='Revolute14'>0 0 0 0 -0 0</pose>
      <inertial>
        <pose>-0.006162 0.012962 -0.010688 0 -0 0</pose>
        <mass>0.0144644</mass>
        <inertia>
          <ixx>8.05433e-06</ixx>
          <ixy>8.71828e-07</ixy>
          <ixz>-2.00672e-06</ixz>
          <iyy>1.1326e-05</iyy>
          <iyz>1.5115e-06</iyz>
          <izz>5.88964e-06</izz>
        </inertia>
      </inertial>
      <collision name='Ring2_collision'>
        <pose>0 -0.0565 0 0 -0 0</pose>
        <geometry>
          <mesh>
            <scale>0.001 0.001 0.001</scale>
            <uri>model://spm_wrist_description/meshes/Ring_v2_2.stl</uri>
          </mesh>
        </geometry>
      </collision>
      <collision name='Ring2_fixed_joint_lump__MiddleArm_collision_1'>
        <pose>0 -0.0565 0 0 -0 0</pose>
        <geometry>
          <mesh>
            <scale>0.001 0.001 0.001</scale>
            <uri>model://spm_wrist_description/meshes/MiddleArm_v2_1.stl</uri>
          </mesh>
        </geometry>
      </collision>
      <visual name='Ring2_visual'>
        <pose>0 -0.0565 0 0 -0 0</pose>
        <geometry>
          <mesh>
            <scale>0.001 0.001 0.001</scale>
            <uri>model://spm_wrist_description/meshes/Ring_v2_2.stl</uri>
          </mesh>
        </geometry>
      </visual>
      <visual name='Ring2_fixed_joint_lump__MiddleArm_visual_1'>
        <pose>0 -0.0565 0 0 -0 0</pose>
        <geometry>
          <mesh>
            <scale>0.001 0.001 0.001</scale>
            <uri>model://spm_wrist_description/meshes/MiddleArm_v2_1.stl</uri>
          </mesh>
        </geometry>
      </visual>
    </link>
    <joint name='PlatformSupportLink2_Joint' type='revolute'>
      <pose relative_to='Ring2'>-0.015908 0.045098 -0.027553 0 -0 0</pose>
      <parent>Ring2</parent>
      <child>PlatformSupportLink2</child>
      <axis>
        <xyz>0.353553 0.707107 0.612372</xyz>
        <limit>
          <lower>-1e+16</lower>
          <upper>1e+16</upper>
        </limit>
        <dynamics>
          <spring_reference>0</spring_reference>
          <spring_stiffness>0</spring_stiffness>
        </dynamics>
      </axis>
    </joint>
    <link name='PlatformSupportLink2'>
      <pose relative_to='PlatformSupportLink2_Joint'>0 0 0 0 -0 0</pose>
      <inertial>
        <pose>0.019527 0.023071 -0.001275 0 -0 0</pose>
        <mass>0.0101513</mass>
        <inertia>
          <ixx>2.757e-06</ixx>
          <ixy>-1.541e-06</ixy>
          <ixz>-8.53e-07</ixz>
          <iyy>3.533e-06</iyy>
          <iyz>1e-08</iyz>
          <izz>4.447e-06</izz>
        </inertia>
      </inertial>
      <collision name='PlatformSupportLink2_collision'>
        <pose>0.015908 -0.101598 0.027553 0 -0 0</pose>
        <geometry>
          <mesh>
            <scale>0.001 0.001 0.001</scale>
            <uri>model://spm_wrist_description/meshes/PlatformSupportLink_v2_2.stl</uri>
          </mesh>
        </geometry>
      </collision>
      <visual name='PlatformSupportLink2_visual'>
        <pose>0.015908 -0.101598 0.027553 0 -0 0</pose>
        <geometry>
          <mesh>
            <scale>0.001 0.001 0.001</scale>
            <uri>model://spm_wrist_description/meshes/PlatformSupportLink_v2_2.stl</uri>
          </mesh>
        </geometry>
      </visual>
    </link>
    <joint name='Revolute15' type='revolute'>
      <pose relative_to='base_link'>0 0.0725 0 0 -0 0</pose>
      <parent>base_link</parent>
      <child>Ring3</child>
      <axis>
        <xyz>0 1 0</xyz>
        <limit>
          <lower>-1e+16</lower>
          <upper>1e+16</upper>
        </limit>
        <dynamics>
          <spring_reference>0</spring_reference>
          <spring_stiffness>0</spring_stiffness>
        </dynamics>
      </axis>
    </joint>
    <link name='Ring3'>
      <pose relative_to='Revolute15'>0 0 0 0 -0 0</pose>
      <inertial>
        <pose>-0.004909 0.009778 0.00849 0 -0 0</pose>
        <mass>0.012968</mass>
        <inertia>
          <ixx>6.48103e-06</ixx>
          <ixy>3.58973e-07</ixy>
          <ixz>1.66033e-06</ixz>
          <iyy>1.05246e-05</iyy>
          <iyz>-6.2147e-07</iyz>
          <izz>4.71927e-06</izz>
        </inertia>
      </inertial>
      <collision name='Ring3_collision'>
        <pose>0 -0.0725 0 0 -0 0</pose>
        <geometry>
          <mesh>
            <scale>0.001 0.001 0.001</scale>
            <uri>model://spm_wrist_description/meshes/Ring_v2_3.stl</uri>
          </mesh>
        </geometry>
      </collision>
      <collision name='Ring3_fixed_joint_lump__ShortArm_collision_1'>
        <pose>0 -0.0725 0 0 -0 0</pose>
        <geometry>
          <mesh>
            <scale>0.001 0.001 0.001</scale>
            <uri>model://spm_wrist_description/meshes/ShortArm_v2_1.stl</uri>
          </mesh>
        </geometry>
      </collision>
      <visual name='Ring3_visual'>
        <pose>0 -0.0725 0 0 -0 0</pose>
        <geometry>
          <mesh>
            <scale>0.001 0.001 0.001</scale>
            <uri>model://spm_wrist_description/meshes/Ring_v2_3.stl</uri>
          </mesh>
        </geometry>
      </visual>
      <visual name='Ring3_fixed_joint_lump__ShortArm_visual_1'>
        <pose>0 -0.0725 0 0 -0 0</pose>
        <geometry>
          <mesh>
            <scale>0.001 0.001 0.001</scale>
            <uri>model://spm_wrist_description/meshes/ShortArm_v2_1.stl</uri>
          </mesh>
        </geometry>
      </visual>
    </link>
    <joint name='PlatformSupportLink3_Joint' type='revolute'>
      <pose relative_to='Ring3'>-0.015906 0.029098 0.027554 0 -0 0</pose>
      <parent>Ring3</parent>
      <child>PlatformSupportLink3</child>
      <axis>
        <xyz>-0.353553 -0.707107 0.612372</xyz>
        <limit>
          <lower>-1e+16</lower>
          <upper>1e+16</upper>
        </limit>
        <dynamics>
          <spring_reference>0</spring_reference>
          <spring_stiffness>0</spring_stiffness>
        </dynamics>
      </axis>
    </joint>
    <link name='PlatformSupportLink3'>
      <pose relative_to='PlatformSupportLink3_Joint'>0 0 0 0 -0 0</pose>
      <inertial>
        <pose>-0.010894 0.022944 -0.016435 0 -0 0</pose>
        <mass>0.0101513</mass>
        <inertia>
          <ixx>4.758e-06</ixx>
          <ixy>7.7e-07</ixy>
          <ixz>-2.99e-07</ixz>
          <iyy>3.552e-06</iyy>
          <iyz>1.33e-06</iyz>
          <izz>2.427e-06</izz>
        </inertia>
      </inertial>
      <collision name='PlatformSupportLink3_collision'>
        <pose>0.015906 -0.101598 -0.027554 0 -0 0</pose>
        <geometry>
          <mesh>
            <scale>0.001 0.001 0.001</scale>
            <uri>model://spm_wrist_description/meshes/PlatformSupportLink_v2_3.stl</uri>
          </mesh>
        </geometry>
      </collision>
      <visual name='PlatformSupportLink3_visual'>
        <pose>0.015906 -0.101598 -0.027554 0 -0 0</pose>
        <geometry>
          <mesh>
            <scale>0.001 0.001 0.001</scale>
            <uri>model://spm_wrist_description/meshes/PlatformSupportLink_v2_3.stl</uri>
          </mesh>
        </geometry>
      </visual>
    </link>
    <joint name='SrtSpur_Joint' type='revolute'>
      <pose relative_to='base_link'>0.015556 0.0352 0.008981 0 -0 0</pose>
      <parent>base_link</parent>
      <child>AxisConnector2</child>
      <axis>
        <xyz>0 1 0</xyz>
        <limit>
          <lower>-1e+16</lower>
          <upper>1e+16</upper>
        </limit>
        <dynamics>
          <spring_reference>0</spring_reference>
          <spring_stiffness>0</spring_stiffness>
        </dynamics>
      </axis>
    </joint>
    <link name='AxisConnector2'>
      <pose relative_to='SrtSpur_Joint'>0 0 0 0 -0 0</pose>
      <inertial>
        <pose>-3.5e-05 0.009749 0 0 -0 0</pose>
        <mass>0.00633253</mass>
        <inertia>
          <ixx>6.94409e-07</ixx>
          <ixy>2.97159e-09</ixy>
          <ixz>-4.0974e-20</ixz>
          <iyy>1.53374e-07</iyy>
          <iyz>8.40773e-18</iyz>
          <izz>6.94424e-07</izz>
        </inertia>
      </inertial>
      <collision name='AxisConnector2_collision'>
        <pose>-0.015556 -0.0352 -0.008981 0 -0 0</pose>
        <geometry>
          <mesh>
            <scale>0.001 0.001 0.001</scale>
            <uri>model://spm_wrist_description/meshes/AxisConnector_v3_2.stl</uri>
          </mesh>
        </geometry>
      </collision>
      <collision name='AxisConnector2_fixed_joint_lump__SrtSpur_collision_1'>
        <pose>-0.015556 -0.0352 -0.008981 0 -0 0</pose>
        <geometry>
          <mesh>
            <scale>0.001 0.001 0.001</scale>
            <uri>model://spm_wrist_description/meshes/SrtSpur_v2_1.stl</uri>
          </mesh>
        </geometry>
      </collision>
      <visual name='AxisConnector2_visual'>
        <pose>-0.015556 -0.0352 -0.008981 0 -0 0</pose>
        <geometry>
          <mesh>
            <scale>0.001 0.001 0.001</scale>
            <uri>model://spm_wrist_description/meshes/AxisConnector_v3_2.stl</uri>
          </mesh>
        </geometry>
      </visual>
      <visual name='AxisConnector2_fixed_joint_lump__SrtSpur_visual_1'>
        <pose>-0.015556 -0.0352 -0.008981 0 -0 0</pose>
        <geometry>
          <mesh>
            <scale>0.001 0.001 0.001</scale>
            <uri>model://spm_wrist_description/meshes/SrtSpur_v2_1.stl</uri>
          </mesh>
        </geometry>
      </visual>
    </link>
    <joint name='MidSpur_Joint' type='revolute'>
      <pose relative_to='base_link'>0 0.0352 -0.017963 0 -0 0</pose>
      <parent>base_link</parent>
      <child>AxisConnector3</child>
      <axis>
        <xyz>0 1 0</xyz>
        <limit>
          <lower>-1e+16</lower>
          <upper>1e+16</upper>
        </limit>
        <dynamics>
          <spring_reference>0</spring_reference>
          <spring_stiffness>0</spring_stiffness>
        </dynamics>
      </axis>
    </joint>
    <link name='AxisConnector3'>
      <pose relative_to='MidSpur_Joint'>0 0 0 0 -0 0</pose>
      <inertial>
        <pose>-3.5e-05 0.010425 0 0 -0 0</pose>
        <mass>0.00633298</mass>
        <inertia>
          <ixx>8.12973e-07</ixx>
          <ixy>3.24305e-09</ixy>
          <ixz>-1.53132e-13</ixz>
          <iyy>1.53374e-07</iyy>
          <iyz>3.43905e-11</iyz>
          <izz>8.12987e-07</izz>
        </inertia>
      </inertial>
      <collision name='AxisConnector3_collision'>
        <pose>0 -0.0352 0.017963 0 -0 0</pose>
        <geometry>
          <mesh>
            <scale>0.001 0.001 0.001</scale>
            <uri>model://spm_wrist_description/meshes/AxisConnector_v3_3.stl</uri>
          </mesh>
        </geometry>
      </collision>
      <collision name='AxisConnector3_fixed_joint_lump__MidSpur_collision_1'>
        <pose>0 -0.0352 0.017963 0 -0 0</pose>
        <geometry>
          <mesh>
            <scale>0.001 0.001 0.001</scale>
            <uri>model://spm_wrist_description/meshes/MidSpur_v2_1.stl</uri>
          </mesh>
        </geometry>
      </collision>
      <visual name='AxisConnector3_visual'>
        <pose>0 -0.0352 0.017963 0 -0 0</pose>
        <geometry>
          <mesh>
            <scale>0.001 0.001 0.001</scale>
            <uri>model://spm_wrist_description/meshes/AxisConnector_v3_3.stl</uri>
          </mesh>
        </geometry>
      </visual>
      <visual name='AxisConnector3_fixed_joint_lump__MidSpur_visual_1'>
        <pose>0 -0.0352 0.017963 0 -0 0</pose>
        <geometry>
          <mesh>
            <scale>0.001 0.001 0.001</scale>
            <uri>model://spm_wrist_description/meshes/MidSpur_v2_1.stl</uri>
          </mesh>
        </geometry>
      </visual>
    </link>
    <static>0</static>

  </model>
</sdf>
